<robot name="simpleHumanoid">
	<link name="base" >
		<inertial>
				<origin rpy = "0 0 0" xyz = "0 0 0" />
			 <mass value = "0.0001" />
			<inertia ixx = "0.0001" ixy = "0" ixz = "0" iyy = "0.0001" iyz = "0" izz = "0.0001" />
		</inertial>
	</link>
	<link name="trunk" >
		<inertial>
				<origin rpy = "0 0 0" xyz = "0.000000 0.280000 0.000000" />
			 <mass value = "6.000000" />
			<inertia ixx = "0.1" ixy = "0" ixz = "0" iyy = "0.1" iyz = "0" izz = "0.1" />
		</inertial>
		<collision>
				<origin rpy = "0 0 0" xyz = "0.000000 0.280000 0.000000" />
			<geometry>
				<box size="0.708000 0.220000 0.360000" />
			</geometry>
		</collision>
	</link>
	<joint name="root" type="fixed" >
		<parent link = "base" />
		<child link="trunk" />
				<origin rpy = "0 0 0" xyz = "0.000000 0.000000 0.000000" />
	</joint>
	<link name="Rthigh" >
		<inertial>
				<origin rpy = "0 0 0" xyz = "0.000000 -0.840000 0.000000" />
			 <mass value = "4.500000" />
			<inertia ixx = "0.1" ixy = "0" ixz = "0" iyy = "0.1" iyz = "0" izz = "0.1" />
		</inertial>
		<collision>
				<origin rpy = "0 0 0" xyz = "0.000000 -0.840000 0.000000" />
			<geometry>
				<box size="0.708000 0.220000 0.360000" />
			</geometry>
		</collision>
	</link>
	<joint name="Rhip" type="spherical" >
		<parent link="trunk" />
		<child link="Rthigh" />
				<origin rpy = "0 0 0" xyz = "0.000000 0.000000 0.339548" />
	</joint>
	<link name="Rshank" >
		<inertial>
				<origin rpy = "0 0 0" xyz = "0.000000 -0.800000 0.000000" />
			 <mass value = "3.000000" />
			<inertia ixx = "0.1" ixy = "0" ixz = "0" iyy = "0.1" iyz = "0" izz = "0.1" />
		</inertial>
		<collision>
				<origin rpy = "0 0 0" xyz = "0.000000 -0.800000 0.000000" />
			<geometry>
				<box size="0.708000 0.220000 0.360000" />
			</geometry>
		</collision>
	</link>
	<joint name="Rknee" type="revolute" >
		<parent link="Rthigh" />
		<child link="Rshank" />
		 <limit effort="1000.0" lower="-3.14" upper="0." velocity="0.5"/>
			<origin rpy = "0 0 0" xyz = "0.000000 -1.686184 0.000000" />
		<axis xyz = "1.000000 0.000000 0.000000" />
	</joint>
	<link name="Rfoot" >
		<inertial>
				<origin rpy = "0 0 0" xyz = "0.180000 -0.090000 0.000000" />
			 <mass value = "1.000000" />
			<inertia ixx = "0.1" ixy = "0" ixz = "0" iyy = "0.1" iyz = "0" izz = "0.1" />
		</inertial>
		<collision>
				<origin rpy = "0 0 0" xyz = "0.180000 -0.090000 0.000000" />
			<geometry>
				<box size="0.708000 0.220000 0.360000" />
			</geometry>
		</collision>
	</link>
	<joint name="Rankle" type="spherical" >
		<parent link="Rshank" />
		<child link="Rfoot" />
				<origin rpy = "0 0 0" xyz = "0.000000 -1.639480 0.000000" />
	</joint>
	<link name="Lthigh" >
		<inertial>
				<origin rpy = "0 0 0" xyz = "0.000000 -0.840000 0.000000" />
			 <mass value = "4.500000" />
			<inertia ixx = "0.1" ixy = "0" ixz = "0" iyy = "0.1" iyz = "0" izz = "0.1" />
		</inertial>
		<collision>
				<origin rpy = "0 0 0" xyz = "0.000000 -0.840000 0.000000" />
			<geometry>
				<box size="0.708000 0.220000 0.360000" />
			</geometry>
		</collision>
	</link>
	<joint name="Lhip" type="spherical" >
		<parent link="trunk" />
		<child link="Lthigh" />
				<origin rpy = "0 0 0" xyz = "0.000000 0.000000 -0.339548" />
	</joint>
	<link name="Lshank" >
		<inertial>
				<origin rpy = "0 0 0" xyz = "0.000000 -0.800000 0.000000" />
			 <mass value = "3.000000" />
			<inertia ixx = "0.1" ixy = "0" ixz = "0" iyy = "0.1" iyz = "0" izz = "0.1" />
		</inertial>
		<collision>
				<origin rpy = "0 0 0" xyz = "0.000000 -0.800000 0.000000" />
			<geometry>
				<box size="0.708000 0.220000 0.360000" />
			</geometry>
		</collision>
	</link>
	<joint name="Lknee" type="revolute" >
		<parent link="Lthigh" />
		<child link="Lshank" />
		<limit effort="1000.0" lower="-3.14" upper="0." velocity="0.5"/>
				<origin rpy = "0 0 0" xyz = "0.000000 -1.686184 0.000000" />
		<axis xyz = "1.000000 0.000000 0.000000" />
	</joint>
	<link name="Lfoot" >
		<inertial>
				<origin rpy = "0 0 0" xyz = "0.180000 -0.090000 0.000000" />
			 <mass value = "1.000000" />
			<inertia ixx = "0.1" ixy = "0" ixz = "0" iyy = "0.1" iyz = "0" izz = "0.1" />
		</inertial>
		<collision>
				<origin rpy = "0 0 0" xyz = "0.180000 -0.090000 0.000000" />
			<geometry>
				<box size="0.708000 0.220000 0.360000" />
			</geometry>
		</collision>
	</link>
	<joint name="Lankle" type="spherical" >
		<parent link="Lshank" />
		<child link="Lfoot" />
				<origin rpy = "0 0 0" xyz = "0.000000 -1.639480 0.000000" />
	</joint>
</robot>
