<?xml version="1.0" encoding="utf-8"?>
<robot name="simpleHumanoid">
	  <link name="base">
		    <inertial>
				     <origin rpy="0 0 0" xyz="0 0 0"/>
			      <mass value="0.0001"/>
			      <inertia ixx="0.0001" ixy="0" ixz="0" iyy="0.0001" iyz="0" izz="0.0001"/>
		    </inertial>
	  </link>
	  <link name="trunk">
		    <inertial>
				     <origin rpy="0 0 0" xyz="0.000000 0.000000 0.038073"/>
			      <mass value="31.794919"/>
			      <inertia ixx="4.833617" ixy="0" ixz="0" iyy="5.090269" iyz="0" izz="2.438196"/>
		    </inertial>
		    <collision>
				     <origin rpy="0 0 0" xyz="0.000000 0.000000 0.000000"/>
			      <geometry>
				        <box size="0.358761 0.156958 0.448451"/>
			      </geometry>
		    </collision>
	  </link>
	  <joint name="root" type="fixed">
		    <parent link="base"/>
		    <child link="trunk"/>
				  <origin rpy="0 0 0" xyz="0.000000 0.000000 0.000000"/>
	  </joint>
	  <link name="Rthigh">
		    <inertial>
				     <origin rpy="0 0 0" xyz="0.000000 0.000000 -0.127499"/>
			      <mass value="8.068834"/>
			      <inertia ixx="1.036740" ixy="0" ixz="0" iyy="1.050981" iyz="0" izz="0.461406"/>
		    </inertial>
		    <collision>
				     <origin rpy="0 0 0" xyz="0.000000 0.000000 -0.176493"/>
			      <geometry>
				        <box size="0.070597 0.070597 0.352986"/>
			      </geometry>
		    </collision>
	  </link>
	  <joint name="Rhip" type="spherical">
		    <parent link="trunk"/>
		    <child link="Rthigh"/>
				  <origin rpy="0 0 0" xyz="0.086883  0.000000 -0.224225"/>
	  </joint>
	  <link name="Rshank">
		    <inertial>
				     <origin rpy="0 0 0" xyz="0.000000 0.000000 -0.167429"/>
			      <mass value="2.625920"/>
			      <inertia ixx="0.265824" ixy="0" ixz="0" iyy="0.269806" iyz="0" izz="0.092590"/>
		    </inertial>
		    <collision>
				     <origin rpy="0 0 0" xyz="0.000000 0.000000 -0.189571"/>
			      <geometry>
				        <box size="0.075828 0.075828 0.379142"/>
			      </geometry>
		    </collision>
	  </link>
	  <joint name="Rknee" type="revolute">
		    <parent link="Rthigh"/>
		    <child link="Rshank"/>
		    <limit effort="1000.0" lower="-3.14" upper="0." velocity="0.5"/>
			   <origin rpy="0 0 0" xyz="0.000000  0.000000 -0.352986"/>
		    <axis xyz="1.0 0.0 0.0"/>
	  </joint>
	  <link name="Rfoot">
		    <inertial>
				     <origin rpy="0 0 0" xyz="0.000000 0.016762 -0.028675"/>
			      <mass value="0.704249"/>
			      <inertia ixx="0.042325" ixy="0" ixz="0" iyy="0.045359" iyz="0" izz="0.021087"/>
		    </inertial>
		    <collision>
				     <origin rpy="0 0 0" xyz="0.000000 0.050356 -0.028675"/>
			      <geometry>
				        <box size="0.066532 0.215412 0.057349"/>
			      </geometry>
		    </collision>
	  </link>
	  <joint name="Rankle" type="spherical">
		    <parent link="Rshank"/>
		    <child link="Rfoot"/>
				  <origin rpy="0 0 0" xyz="0.000000  0.000000 -0.379142"/>
	  </joint>
	  <link name="Lthigh">
		    <inertial>
				     <origin rpy="0 0 0" xyz="0.000000 0.000000 -0.127499"/>
			      <mass value="8.068834"/>
			      <inertia ixx="1.036740" ixy="0" ixz="0" iyy="1.050981" iyz="0" izz="0.461406"/>
		    </inertial>
		    <collision>
				     <origin rpy="0 0 0" xyz="0.000000 0.000000 -0.176493"/>
			      <geometry>
				        <box size="0.070597 0.070597 0.352986"/>
			      </geometry>
		    </collision>
	  </link>
	  <joint name="Lhip" type="spherical">
		    <parent link="trunk"/>
		    <child link="Lthigh"/>
				  <origin rpy="0 0 0" xyz="-0.086883  0.000000 -0.224225"/>
	  </joint>
	  <link name="Lshank">
		    <inertial>
				     <origin rpy="0 0 0" xyz="0.000000 0.000000 -0.167429"/>
			      <mass value="2.625920"/>
			      <inertia ixx="0.265824" ixy="0" ixz="0" iyy="0.269806" iyz="0" izz="0.092590"/>
		    </inertial>
		    <collision>
				     <origin rpy="0 0 0" xyz="0.000000 0.000000 -0.189571"/>
			      <geometry>
				        <box size="0.075828 0.075828 0.379142"/>
			      </geometry>
		    </collision>
	  </link>
	  <joint name="Lknee" type="revolute">
		    <parent link="Lthigh"/>
		    <child link="Lshank"/>
		    <limit effort="1000.0" lower="-3.14" upper="0." velocity="0.5"/>
				  <origin rpy="0 0 0" xyz="0.000000  0.000000 -0.352986"/>
		    <axis xyz="1.0 0.0 0.0"/>
	  </joint>
	  <link name="Lfoot">
		    <inertial>
				     <origin rpy="0 0 0" xyz="0.000000 0.016762 -0.028675"/>
			      <mass value="0.704249"/>
			      <inertia ixx="0.042325" ixy="0" ixz="0" iyy="0.045359" iyz="0" izz="0.021087"/>
		    </inertial>
		    <collision>
				     <origin rpy="0 0 0" xyz="0.000000 0.050356 -0.028675"/>
			      <geometry>
				        <box size="0.066532 0.215412 0.057349"/>
			      </geometry>
		    </collision>
	  </link>
	  <joint name="Lankle" type="spherical">
		    <parent link="Lshank"/>
		    <child link="Lfoot"/>
				  <origin rpy="0 0 0" xyz="0.000000  0.000000 -0.379142"/>
	  </joint>
</robot>